- [例外発生時の挙動](#例外発生時の挙動)
  - [概要](#概要)
  - [例](#例)


# 例外発生時の挙動

## 概要

例外発生時に、きちんと例外を catch していれば、  
try ブロック内の例外発生以降の処理は中止されますが、  
catch ブロック終了後の後続処理は継続されます。


## 例

以下のサンプルコードについて考えます。

サンプルコード内に、例外が発生した場合に実行される部分と、実行されない部分を明記しました。

```java
public class MainActivity extends AppCompatActivity {

    @Override
    protected void onCreate(Bundle savedInstanceState) {
        super.onCreate(savedInstanceState);
        setContentView(R.layout.activity_main);

        exceptionMethod();

        // 例外が発生しても catch していれば、ここは実行されます。
        Log.d("test", "exceptionMethod から出たところ");

    }

    private void exceptionMethod() {

        int value = 10;

        try {
            // 0 で除算して例外を発生させる。
            value = value / 0;
            // ここは実行されません。
            Log.d("test", "try ブロックの最後");

        } catch (ArithmeticException e) {
            //例外内容を出力
            e.printStackTrace();
            // 例外が発生してもここは実行されます。
            Log.d("test", "catch ブロック内");
        } finally {
            // 例外が発生しても発生しなくてもここは実行されます。
            Log.d("test", "finally ブロック内");

            // もし、 catch ブロックが存在せず、 finally ブロックのみが存在している場合に例外が発生すると、
            // finally ブロックの実行後にアプリがクラッシュします。
            // その場合は、 finally ブロックの後続処理は実施されません。
        }

        // 例外が発生しても catch していれば、ここは実行されます。
        Log.d("test", "catch ブロックから出たところ");
    }
}
```




